Workbook

Sheet 📋 Raw Data
A1: Train No | B1: Train Name | C1: Source Station | D1: Departure | E1: Arrival | F1: Distance (km) | G1: Destination Station | H1: Days of Week | I1: Classes | J1: Intermediate Stops
A2: 10101 | B2: RN MADGAON EXP Train | C2: Ratnagiri | D2: 1:40 | E2: 9:00 | F2: 239 | G2: Madgaon | H2: MON,TUE,WED,THU,FRI,SAT,SUN | I2: 1A,2A,3A,CC,FC,SL,2S,3E,GN | J2: Ratnagiri (arr=First,dep=01:40) | Rajapur Road (arr=02:41,dep=02:42) | Vaibhavwadi Road (arr=03:01,dep=03:02) | Kankavli (arr=03:43,dep=03:44) | Sindhudurg (arr=04:01,dep=04:02) | Kudal (arr=04:15,dep=04:16) | Zarap (arr=04:27,dep=04:28) | Sawantwadi Road (arr=04:41,dep=04:42) | Madure H (arr=04:53,dep=04:54) | Pernem (arr=05:16,dep=05:17) | Thivim (arr=06:01,dep=06:02) | Karmali (arr=06:31,dep=06:32) | Verna (arr=06:45,dep=06:46) | Madgaon (arr=09:00,dep=Last)
A3: 10102 | B3: MADGAON RN EXP Train | C3: Madgaon | D3: 19:00 | E3: 1:54 | F3: 239 | G3: Ratnagiri | H3: MON,TUE,WED,THU,FRI,SAT,SUN | I3: 1A,2A,3A,CC,FC,SL,2S,3E,GN | J3: Madgaon (arr=First,dep=19:00) | Verna (arr=19:19,dep=19:20) | Karmali (arr=19:35,dep=19:36) | Thivim (arr=19:56,dep=19:57) | Pernem (arr=20:09,dep=20:10) | Madure H (arr=20:30,dep=20:31) | Sawantwadi Road (arr=20:42,dep=20:43) | Zarap (arr=20:57,dep=20:58) | Kudal (arr=21:19,dep=21:20) | Sindhudurg (arr=21:35,dep=21:36) | Kankavli (arr=21:56,dep=21:57) | Vaibhavwadi Road (arr=22:26,dep=22:27) | Rajapur Road (arr=22:46,dep=22:47) | Ratnagiri (arr=01:55,dep=Last)
A4: 10103 | B4: MANDOVI EXPRESS | C4: C Shivaji Maharaj T | D4: 7:10 | E4: 19:10 | F4: 765 | G4: Madgaon | H4: MON,TUE,WED,THU,FRI,SAT,SUN | I4: GN,3E,SL,3A,2A,1A | J4: C Shivaji Maharaj T (arr=First,dep=07:10) | Dadar (arr=07:22,dep=07:25) | Thane (arr=07:51,dep=07:55) | Panvel (arr=08:25,dep=08:30) | Mangaon (arr=10:14,dep=10:16) | Khed (arr=11:18,dep=11:20) | Chiplun (arr=11:46,dep=11:48) | Sangmeshwar (arr=12:22,dep=12:24) | Ratnagiri (arr=13:30,dep=13:35) | Adavali (arr=14:03,dep=14:05) | Rajapur Road (arr=14:40,dep=14:42) | Vaibhavwadi Road (arr=14:56,dep=14:58) | Kankavli (arr=15:30,dep=15:32) | Sindhudurg (arr=15:50,dep=15:52) | Kudal (arr=16:04,dep=16:06) | Sawantwadi Road (arr=16:28,dep=16:30) | Pernem (arr=17:15,dep=17:17) | Thivim (arr=17:30,dep=17:32) | Karmali (arr=17:54,dep=17:56) | Madgaon (arr=19:10,dep=Last)
A5: 10104 | B5: MANDOVI EXPRESS | C5: Madgaon | D5: 9:15 | E5: 21:45 | F5: 765 | G5: C Shivaji Maharaj T | H5: MON,TUE,WED,THU,FRI,SAT,SUN | I5: GN,3E,SL,3A,2A,1A | J5: Madgaon (arr=First,dep=09:15) | Karmali (arr=09:44,dep=09:46) | Thivim (arr=10:06,dep=10:08) | Pernem (arr=10:20,dep=10:22) | Sawantwadi Road (arr=10:40,dep=10:42) | Kudal (arr=11:02,dep=11:04) | Sindhudurg (arr=11:15,dep=11:17) | Kankavli (arr=11:30,dep=11:32) | Vaibhavwadi Road (arr=11:56,dep=11:58) | Rajapur Road (arr=12:20,dep=12:22) | Adavali (arr=13:20,dep=13:22) | RL Ratnagiri (arr=14:25,dep=14:30) | Sangmeshwar (arr=15:02,dep=15:04) | Chiplun (arr=15:34,dep=15:36) | Khed (arr=16:06,dep=16:08) | Mangaon (arr=17:06,dep=17:08) | Panvel (arr=18:57,dep=19:00) | Thane (arr=20:37,dep=20:40) | Dadar (arr=21:07,dep=21:10) | C Shivaji Maharaj T (arr=21:45,dep=Last)
A6: 10105 | B6: DIVA SWV EXPRESS Train | C6: Diva Jn | D6: 6:25 | E6: 18:30 | F6: 613 | G6: Sawantwadi Road | H6: MON,TUE,WED,THU,FRI,SAT,SUN | I6: 1A,2A,3A,CC,FC,SL,2S,3E,GN | J6: Diva Jn (arr=First,dep=06:25) | Kalamboli (arr=06:39,dep=06:40) | Panvel (arr=06:55,dep=07:00) | Apta (arr=07:17,dep=07:18) | Jite (arr=07:27,dep=07:28) | Pen (arr=07:35,dep=07:36) | Roha (arr=08:50,dep=08:55) | Kolad (arr=09:20,dep=09:21) | Mangaon (arr=09:30,dep=09:31) | Goregaon Road H (arr=09:40,dep=09:41) | Veer (arr=10:01,dep=10:02) | Sape Wamne H (arr=10:10,dep=10:11) | Karanjadi (arr=10:21,dep=10:22) | Vinhere (arr=10:32,dep=10:33) | Khed (arr=11:00,dep=11:01) | Anjani (arr=11:11,dep=11:12) | Chiplun (arr=11:30,dep=11:35) | Savarda (arr=11:54,dep=11:55) | Aravali Road (arr=12:10,dep=12:11) | Sangmeshwar (arr=12:39,dep=12:40) | Ratnagiri (arr=14:05,dep=14:10) | Nivasar (arr=14:26,dep=14:27) | Adavali (arr=14:41,dep=14:42) | Veravali (H (arr=14:52,dep=14:53) | Vilavade (arr=15:08,dep=15:09) | Saundal Halt (arr=15:19,dep=15:20) | Rajapur Road (arr=15:44,dep=15:45) | Kharepatan Road (arr=15:55,dep=15:56) | Vaibhavwadi Road (arr=16:06,dep=16:07) | Achirne (arr=16:17,dep=16:18) | Nandgaon Road (arr=16:28,dep=16:29) | Kankavli (arr=16:40,dep=16:41) | Sindhudurg (arr=16:53,dep=16:54) | Kudal (arr=17:10,dep=17:11) | Zarap (arr=17:30,dep=17:31) | Sawantwadi Road (arr=18:30,dep=Last)
A7: 10106 | B7: SWV DIVA EXPRESS Train | C7: Sawantwadi Road | D7: 8:24 | E7: 20:10 | F7: 613 | G7: Diva Jn | H7: MON,TUE,WED,THU,FRI,SAT,SUN | I7: 1A,2A,3A,CC,FC,SL,2S,3E,GN | J7: Sawantwadi Road (arr=First,dep=08:25) | Zarap (arr=08:35,dep=08:36) | Kudal (arr=08:47,dep=08:48) | Sindhudurg (arr=08:57,dep=08:58) | Kankavli (arr=09:17,dep=09:18) | Nandgaon Road (arr=09:32,dep=09:33) | Achirne (arr=09:41,dep=09:42) | Vaibhavwadi Road (arr=09:53,dep=09:54) | Kharepatan Road (arr=10:02,dep=10:03) | Rajapur Road (arr=10:12,dep=10:13) | Vilavade (arr=10:31,dep=10:32) | Veravali (H (arr=10:45,dep=10:46) | Adavali (arr=10:57,dep=10:58) | Nivasar (arr=11:11,dep=11:12) | Ratnagiri (arr=12:10,dep=12:15) | Sangmeshwar (arr=13:01,dep=13:02) | Aravali Road (arr=13:13,dep=13:14) | Savarda (arr=13:25,dep=13:26) | Chiplun (arr=13:42,dep=13:47) | Anjani (arr=13:59,dep=14:00) | Khed (arr=14:11,dep=14:12) | Vinhere (arr=14:35,dep=14:36) | Karanjadi (arr=14:46,dep=14:47) | Sape Wamne H (arr=14:57,dep=14:58) | Veer (arr=15:30,dep=15:31) | Goregaon Road H (arr=15:40,dep=15:41) | Mangaon (arr=16:00,dep=16:01) | Kolad (arr=16:20,dep=16:21) | Roha (arr=17:05,dep=17:10) | Pen (arr=18:00,dep=18:01) | Jite (arr=18:14,dep=18:15) | Apta (arr=18:28,dep=18:29) | Panvel (arr=18:47,dep=18:50) | Kalamboli (arr=19:00,dep=19:01) | Diva Jn (arr=20:10,dep=Last)
A8: 10107 | B8: MAO-MAQ MEMU EXPRESS Train | C8: Madgaon | D8: 4:00 | E8: 11:15 | F8: 321 | G8: Mangalore Central | H8: SUN | I8: 1A,2A,3A,CC,FC,SL,2S,3E,GN | J8: Madgaon (arr=First,dep=04:00) | Cancona (arr=04:30,dep=04:31) | Asnoti (arr=04:50,dep=04:51) | Karwar (arr=05:00,dep=05:01) | Harwada (arr=05:11,dep=05:12) | Ankola (arr=05:22,dep=05:23) | Gokarna Road (arr=05:34,dep=05:35) | Mirjan (arr=05:42,dep=05:43) | Kumta (arr=05:50,dep=05:51) | Honnavar (arr=06:02,dep=06:03) | Manki (arr=06:19,dep=06:20) | Murdeshwar (arr=06:30,dep=06:31) | Bhatkal (arr=06:52,dep=06:53) | Shiroor (arr=07:01,dep=07:02) | Mookambika Road (arr=07:10,dep=07:11) | Senapura (arr=07:40,dep=07:41) | Kundapura (arr=07:56,dep=07:57) | Barkur (arr=08:10,dep=08:11) | Udupi (arr=08:30,dep=08:31) | Padubidri (arr=08:41,dep=08:42) | Mulki (arr=09:19,dep=09:20) | Surathkal (arr=09:40,dep=09:41) | Mangalore Jn (arr=10:38,dep=10:40) | Mangalore Central (arr=11:15,dep=Last)
A9: 10108 | B9: MAQ-MAO MEMU EXPRESS Train | C9: Mangalore Central | D9: 15:30 | E9: 22:20 | F9: 321 | G9: Madgaon | H9: SUN | I9: 1A,2A,3A,CC,FC,SL,2S,3E,GN | J9: Mangalore Central (arr=First,dep=15:30) | Mangalore Jn (arr=15:40,dep=15:42) | Surathkal (arr=16:33,dep=16:34) | Mulki (arr=16:43,dep=16:44) | Padubidri (arr=16:54,dep=16:55) | Udupi (arr=17:10,dep=17:11) | Barkur (arr=17:26,dep=17:27) | Kundapura (arr=17:40,dep=17:41) | Senapura (arr=17:51,dep=17:52) | Mookambika Road (arr=18:02,dep=18:03) | Shiroor (arr=18:11,dep=18:12) | Bhatkal (arr=18:22,dep=18:23) | Murdeshwar (arr=18:35,dep=18:36) | Manki (arr=18:45,dep=18:46) | Honnavar (arr=19:00,dep=19:01) | Kumta (arr=19:18,dep=19:19) | Mirjan (arr=19:28,dep=19:29) | Gokarna Road (arr=19:40,dep=19:41) | Ankola (arr=19:51,dep=19:52) | Harwada (arr=20:02,dep=20:03) | Karwar (arr=20:15,dep=20:16) | Asnoti (arr=20:24,dep=20:25) | Cancona (arr=20:50,dep=20:51) | Madgaon (arr=22:20,dep=Last)
A10: 10111 | B10: KONKAN KANYA EXP Train | C10: C Shivaji Maharaj T | D10: 23:05 | E10: 10:45 | F10: 765 | G10: Madgaon | H10: MON,TUE,WED,THU,FRI,SAT,SUN | I10: 1A,2A,3A,CC,FC,SL,2S,3E,GN | J10: C Shivaji Maharaj T (arr=First,dep=23:05) | Dadar (arr=23:17,dep=23:20) | Thane (arr=23:45,dep=23:50) | Panvel (arr=00:25,dep=00:30) | Khed (arr=03:04,dep=03:06) | Chiplun (arr=03:30,dep=03:32) | Sangmeshwar (arr=04:02,dep=04:04) | Ratnagiri (arr=04:45,dep=04:50) | Vilavade (arr=05:34,dep=05:36) | Rajapur Road (arr=05:50,dep=05:52) | Vaibhavwadi Road (arr=06:10,dep=06:12) | Kankavli (arr=06:42,dep=06:44) | Sindhudurg (arr=07:00,dep=07:02) | Kudal (arr=07:12,dep=07:14) | Sawantwadi Road (arr=07:32,dep=07:34) | Pernem (arr=07:56,dep=07:58) | Thivim (arr=08:10,dep=08:12) | Karmali (arr=08:32,dep=08:34) | Madgaon (arr=10:45,dep=Last)
A11: 10112 | B11: KONKAN KANYA EXP Train | C11: PQ Madgaon | D11: 18:00 | E11: 5:40 | F11: 765 | G11: C Shivaji Maharaj T | H11: MON,TUE,WED,THU,FRI,SAT,SUN | I11: 1A,2A,3A,CC,FC,SL,2S,3E,GN | J11: PQ Madgaon (arr=First,dep=18:00) | Karmali (arr=18:30,dep=18:32) | Thivim (arr=18:50,dep=18:52) | Pernem (arr=19:05,dep=19:07) | Sawantwadi Road (arr=19:26,dep=19:28) | Kudal (arr=19:46,dep=19:48) | Sindhudurg (arr=20:02,dep=20:04) | Kankavli (arr=20:18,dep=20:20) | Vaibhavwadi Road (arr=21:08,dep=21:10) | Rajapur Road (arr=21:25,dep=21:27) | Vilavade (arr=21:52,dep=21:54) | RL Ratnagiri (arr=22:50,dep=22:55) | Sangmeshwar (arr=23:40,dep=23:42) | Chiplun (arr=00:20,dep=00:22) | Khed (arr=00:45,dep=00:47) | Panvel (arr=03:55,dep=04:00) | Thane (arr=04:42,dep=04:45) | Dadar (arr=05:12,dep=05:15) | C Shivaji Maharaj T (arr=05:40,dep=Last)
A12: 10115 | B12: BDTS MAO EXPRESS Train | C12: Bandra Terminus | D12: 6:50 | E12: 22:40 | F12: 801 | G12: Madgaon | H12: MON,TUE,WED,THU,FRI,SAT,SUN | I12: 1A,2A,3A,CC,FC,SL,2S,3E,GN | J12: Bandra Terminus (arr=First,dep=06:50) | Borivali (arr=07:13,dep=07:15) | Vasai Road (arr=08:00,dep=08:10) | Bhivandi Road (arr=08:50,dep=08:52) | Panvel (arr=09:42,dep=09:45) | Roha (arr=11:15,dep=11:20) | Veer (arr=12:00,dep=12:02) | Chiplun (arr=13:25,dep=13:27) | Ratnagiri (arr=15:35,dep=15:40) | Kankavli (arr=18:00,dep=18:02) | Sindhudurg (arr=18:20,dep=18:22) | Sawantwadi Road (arr=19:30,dep=19:32) | Thivim (arr=20:30,dep=20:32) | Karmali (arr=21:00,dep=21:02) | Madgaon (arr=22:40,dep=Last)
A13: 10116 | B13: MAO BDTS EXPRESS Train | C13: Madgaon | D13: 7:39 | E13: 23:40 | F13: 801 | G13: Bandra Terminus | H13: MON,TUE,WED,THU,FRI,SAT,SUN | I13: 1A,2A,3A,CC,FC,SL,2S,3E,GN | J13: Madgaon (arr=First,dep=07:40) | Karmali (arr=08:10,dep=08:12) | Thivim (arr=08:32,dep=08:34) | Sawantwadi Road (arr=09:00,dep=09:02) | Sindhudurg (arr=09:36,dep=09:38) | Kankavli (arr=09:50,dep=09:52) | RL Ratnagiri (arr=13:20,dep=13:25) | Chiplun (arr=15:20,dep=15:22) | Veer (arr=17:30,dep=17:32) | Roha (arr=18:45,dep=18:47) | Panvel (arr=19:57,dep=20:00) | Bhivandi Road (arr=21:05,dep=21:07) | Vasai Road (arr=21:40,dep=21:45) | Borivali (arr=22:28,dep=22:30) | Bandra Terminus (arr=23:40,dep=Last)
... A3677: 22008 | B3677: SHATABDI EXP | C3677: Mysore Jn | D3677: 14:15 | E3677: 21:25 | F3677: 500 | G3677: Mgr Chennai Ctr | H3677: WED | I3677: EC,1A | J3677: Mysore Jn (arr=First,dep=14:15) | Ksr Bengaluru (arr=16:15,dep=16:25) | Katpadi Jn (arr=19:23,dep=19:25) | Mgr Chennai Ctr (arr=21:25,dep=Last)
A3678: 22009 | B3678: SHATABDI EXP | C3678: Mumbai Central | D3678: 6:25 | E3678: 12:45 | F3678: 491 | G3678: Ahmedabad Jn | H3678: SUN | J3678: Mumbai Central (arr=First,dep=06:25) | Borivali (arr=06:56,dep=06:59) | Vapi (arr=08:23,dep=08:25) | Surat (arr=09:31,dep=09:36) | Bharuch Jn (arr=10:13,dep=10:14) | Vadodara Jn (arr=11:04,dep=11:09) | Anand Jn (arr=11:36,dep=11:38) | Nadiad Jn (arr=11:52,dep=11:54) | Ahmedabad Jn (arr=12:45,dep=Last)
A3679: 22010 | B3679: SHATABDI EXP Train | C3679: Ahmedabad Jn | D3679: 14:40 | E3679: 21:20 | F3679: 491 | G3679: Mumbai Central | H3679: SUN | I3679: 1A,2A,3A,CC,FC,SL,2S,3E,GN | J3679: Ahmedabad Jn (arr=First,dep=14:40) | Nadiad Jn (arr=15:17,dep=15:19) | Anand Jn (arr=15:38,dep=15:40) | Vadodara Jn (arr=16:19,dep=16:24) | Bharuch Jn (arr=17:06,dep=17:08) | Surat (arr=17:48,dep=17:53) | Vapi (arr=18:53,dep=18:55) | Borivali (arr=20:31,dep=20:34) | Mumbai Central (arr=21:20,dep=Last)
A3680: 22025 | B3680: SHATABDI EXP Train | C3680: Pune Jn | D3680: 5:50 | E3680: 14:20 | F3680: 597 | G3680: Secunderabad Jn | H3680: TUE | I3680: 1A,2A,3A,CC,FC,SL,2S,3E,GN | J3680: Pune Jn (arr=First,dep=05:50) | Solapur Jn (arr=09:10,dep=09:13) | Gulbarga (arr=10:40,dep=10:42) | Wadi (arr=11:27,dep=11:30) | Tandur (arr=12:18,dep=12:20) | Vikarabad Jn (arr=12:54,dep=12:55) | Begampet (arr=13:39,dep=13:40) | Secunderabad Jn (arr=14:20,dep=Last)
A3681: 22026 | B3681: PUNE SHATABDI Train | C3681: Secunderabad Jn | D3681: 14:45 | E3681: 23:10 | F3681: 597 | G3681: Pune Jn | H3681: TUE | I3681: 1A,2A,3A,CC,FC,SL,2S,3E,GN | J3681: Secunderabad Jn (arr=First,dep=14:45) | Begampet (arr=14:53,dep=14:55) | Vikarabad Jn (arr=15:44,dep=15:45) | Tandur (arr=16:14,dep=16:15) | Wadi (arr=17:19,dep=17:22) | Gulbarga (arr=17:53,dep=17:56) | Solapur Jn (arr=19:37,dep=19:40) | Pune Jn (arr=23:10,dep=Last)
A3682: 22101 | B3682: LTT MADURAI EXP | C3682: PQ Lokmanyatilak | D3682: 13:15 | E3682: 18:30 | F3682: 1709 | G3682: Madurai Jn | H3682: MON,TUE,WED,THU,FRI,SAT,SUN | I3682: GN,SL,3A,2A | J3682: PQ Lokmanyatilak (arr=First,dep=13:15) | Thane (arr=13:36,dep=13:38) | Kalyan Jn (arr=14:02,dep=14:05) | Karjat (arr=14:48,dep=14:50) | RL Pune Jn (arr=16:35,dep=16:40) | Daund Jn (arr=18:00,dep=18:05) | RL Solapur Jn (arr=20:30,dep=20:35) | Kalaburagi (arr=21:57,dep=22:00) | Shahabad (arr=22:40,dep=22:42) | Wadi (arr=23:05,dep=23:10) | Raichur (arr=00:38,dep=00:40) | Manthralayam Road (arr=01:03,dep=01:05) | Adoni (arr=01:38,dep=01:40) | RL Guntakal Jn (arr=02:45,dep=02:50) | Gooty Jn (arr=03:19,dep=03:20) | Cuddapah (arr=05:23,dep=05:25) | Razampeta (arr=06:08,dep=06:10) | Renigunta Jn (arr=07:50,dep=08:00) | Tiruttani (arr=08:58,dep=09:00) | Kanchipuram (arr=10:03,dep=10:05) | Chengalpattu Jn (arr=10:53,dep=10:55) | Villupuram Jn (arr=12:25,dep=12:30) | Vriddhachalam Jn (arr=13:13,dep=13:15) | Tiruchchirappalli Jn (arr=15:25,dep=15:30) | Dindigul Jn (arr=16:55,dep=17:00) | Madurai Jn (arr=18:30,dep=Last)
A3683: 22102 | B3683: MDU LTT SF EXP Train | C3683: Madurai Jn | D3683: 16:00 | E3683: 20:30 | F3683: 1709 | G3683: Lokmanyatilak | H3683: MON,TUE,WED,THU,FRI,SAT,SUN | I3683: 1A,2A,3A,CC,FC,SL,2S,3E,GN | J3683: Madurai Jn (arr=First,dep=16:00) | PQ Dindigul Jn (arr=16:55,dep=17:00) | Tiruchchirappalli Jn (arr=18:25,dep=18:30) | Vriddhachalam Jn (arr=20:00,dep=20:02) | Villupuram Jn (arr=21:13,dep=21:15) | Chengalpattu Jn (arr=22:38,dep=22:40) | Kanchipuram (arr=23:13,dep=23:15) | Tiruttani (arr=00:03,dep=00:05) | RL Renigunta Jn (arr=01:00,dep=01:10) | Razampeta (arr=02:09,dep=02:10) | Cuddapah (arr=02:58,dep=03:00) | Gooty Jn (arr=05:19,dep=05:20) | Guntakal Jn (arr=05:50,dep=06:00) | Adoni (arr=06:43,dep=06:45) | Manthralayam Road (arr=07:18,dep=07:20) | Raichur (arr=07:58,dep=08:00) | Wadi (arr=10:10,dep=10:15) | Shahabad (arr=10:27,dep=10:28) | RL Kalaburagi (arr=10:52,dep=10:55) | Solapur Jn (arr=12:20,dep=12:25) | Daund Jn (arr=15:05,dep=15:10) | Pune Jn (arr=16:35,dep=16:40) | Kalyan Jn (arr=19:27,dep=19:30) | Thane (arr=19:52,dep=19:55) | Lokmanyatilak (arr=20:30,dep=Last)
A3684: 22103 | B3684: LTT AYODHYA EXP Train | C3684: Lokmanyatilak | D3684: 13:35 | E3684: 17:30 | F3684: 1600 | G3684: Ayodhya Cantt | H3684: MON,TUE,WED,THU,FRI,SAT,SUN | I3684: 1A,2A,3A,CC,FC,SL,2S,3E,GN | J3684: Lokmanyatilak (arr=First,dep=13:35) | Kalyan Jn (arr=14:22,dep=14:25) | PQ Nasik Road (arr=16:58,dep=17:00) | Jalgaon Jn (arr=19:38,dep=19:40) | RL Bhusaval Jn (arr=20:15,dep=20:20) | Itarsi Jn (arr=01:15,dep=01:25) | Jabalpur (arr=04:40,dep=04:50) | Katni (arr=05:55,dep=06:00) | Satna (arr=07:10,dep=07:15) | Manikpur Jn (arr=09:05,dep=09:07) | RL Prayagraj Jn (arr=11:10,dep=11:35) | Janghai Jn (arr=12:46,dep=12:48) | Mariahu (arr=13:23,dep=13:25) | Jaunpur Jn (arr=14:01,dep=14:03) | Shahganj Jn (arr=14:58,dep=15:00) | Akbarpur Jn (arr=15:41,dep=15:43) | Ayodhya Cantt (arr=17:30,dep=Last)
A3685: 22104 | B3685: LTT EXPRESS Train | C3685: Ayodhya Cantt | D3685: 23:10 | E3685: 3:45 | F3685: 1600 | G3685: Lokmanyatilak | H3685: MON,TUE,WED,THU,FRI,SAT,SUN | I3685: 1A,2A,3A,CC,FC,SL,2S,3E,GN | J3685: Ayodhya Cantt (arr=First,dep=23:10) | Akbarpur Jn (arr=00:16,dep=00:18) | Shahganj Jn (arr=00:58,dep=01:00) | Jaunpur Jn (arr=01:36,dep=01:38) | Mariahu (arr=02:08,dep=02:10) | Janghai Jn (arr=02:47,dep=02:48) | RL Prayagraj Jn (arr=05:00,dep=05:20) | Manikpur Jn (arr=07:28,dep=07:30) | Satna (arr=08:20,dep=08:25) | Katni (arr=09:33,dep=09:35) | Jabalpur (arr=10:45,dep=10:55) | RL Itarsi Jn (arr=14:40,dep=14:50) | Bhusaval Jn (arr=19:10,dep=19:15) | RL Jalgaon Jn (arr=19:43,dep=19:45) | Nasik Road (arr=22:40,dep=22:42) | Kalyan Jn (arr=02:32,dep=02:35) | Lokmanyatilak (arr=03:45,dep=Last)
A3686: 22105 | B3686: INDRAYANI EXP Train | C3686: C Shivaji Maharaj T | D3686: 5:40 | E3686: 9:05 | F3686: 192 | G3686: Pune Jn | H3686: MON,TUE,WED,THU,FRI,SAT,SUN | I3686: 1A,2A,3A,CC,FC,SL,2S,3E,GN | J3686: C Shivaji Maharaj T (arr=First,dep=05:40) | Dadar (arr=05:51,dep=05:53) | Thane (arr=06:14,dep=06:16) | Kalyan Jn (arr=06:33,dep=06:35) | Karjat (arr=07:13,dep=07:15) | Lonavla (arr=07:58,dep=08:00) | Shivaji Nagar (arr=08:49,dep=08:50) | Pune Jn (arr=09:05,dep=Last)
A3687: 22106 | B3687: INDRAYANI EXP Train | C3687: Pune Jn | D3687: 18:35 | E3687: 22:00 | F3687: 192 | G3687: C Shivaji Maharaj T | H3687: MON,TUE,WED,THU,FRI,SAT,SUN | I3687: 1A,2A,3A,CC,FC,SL,2S,3E,GN | J3687: Pune Jn (arr=First,dep=18:35) | Lonavla (arr=19:28,dep=19:30) | Karjat (arr=20:13,dep=20:15) | Kalyan Jn (arr=20:50,dep=20:52) | Thane (arr=21:08,dep=21:10) | Dadar (arr=21:33,dep=21:35) | C Shivaji Maharaj T (arr=22:00,dep=Last)
A3688: 22107 | B3688: CSMT LATUR EXP Train | C3688: C Shivaji Maharaj T | D3688: 21:00 | E3688: 6:30 | F3688: 530 | G3688: Latur | H3688: MON,TUE,WED,THU,FRI,SAT,SUN | I3688: 1A,2A,3A,CC,FC,SL,2S,3E,GN | J3688: C Shivaji Maharaj T (arr=First,dep=21:00) | Dadar (arr=21:11,dep=21:13) | Thane (arr=21:33,dep=21:35) | Kalyan Jn (arr=21:52,dep=21:55) | Karjat (arr=22:42,dep=22:45) | Pune Jn (arr=00:30,dep=00:35) | Daund Jn (arr=01:50,dep=01:52) | Kurduvadi (arr=03:10,dep=03:15) | Barsi Town (arr=04:00,dep=04:02) | Dharashiv (arr=04:37,dep=04:40) | Latur (arr=06:30,dep=Last)
A3689: 22108 | B3689: LATUR CSMT EXP | C3689: Latur | D3689: 22:30 | E3689: 8:00 | F3689: 530 | G3689: C Shivaji Maharaj T | H3689: MON,TUE,WED,THU,FRI,SAT,SUN | I3689: GN,SL,3A,2A,1A | J3689: Latur (arr=First,dep=22:30) | Dharashiv (arr=23:33,dep=23:35) | Barsi Town (arr=00:08,dep=00:10) | Kurduvadi (arr=01:05,dep=01:10) | Daund Jn (arr=02:45,dep=02:50) | Pune Jn (arr=04:05,dep=04:10) | Karjat (arr=05:48,dep=05:50) | Kalyan Jn (arr=06:37,dep=06:40) | Thane (arr=07:00,dep=07:02) | Dadar (arr=07:22,dep=07:25) | C Shivaji Maharaj T (arr=08:00,dep=Last)
A3690: 22109 | B3690: LTT BPQ EXPRESS Train | C3690: Lokmanyatilak | D3690: 21:45 | E3690: 12:10 | F3690: 875 | G3690: Balharshah | H3690: MON,TUE,WED,THU,FRI,SAT,SUN | I3690: 1A,2A,3A,CC,FC,SL,2S,3E,GN | J3690: Lokmanyatilak (arr=First,dep=21:45) | Thane (arr=22:03,dep=22:05) | Kalyan Jn (arr=22:22,dep=22:25) | Nasik Road (arr=00:47,dep=00:50) | Bhusaval Jn (arr=04:30,dep=04:35) | Malkapur (arr=05:20,dep=05:22) | Akola Jn (arr=06:45,dep=06:50) | Badnera Jn (arr=07:52,dep=07:55) | Dhamangaon (arr=08:39,dep=08:40) | Pulgaon Jn (arr=08:55,dep=08:56) | Wardha Jn (arr=09:18,dep=09:20) | Hinganghat (arr=09:50,dep=09:51) | Warora (arr=10:19,dep=10:20) | Chandrapur Maharashtra (arr=10:56,dep=10:58) | Balharshah (arr=12:10,dep=Last)
... A5006: 53229 | B5006: RGD-FUT PASSENGER Train | C5006: Rajgir | D5006: 7:00 | E5006: 10:25 | F5006: 68 | G5006: Fatuha | H5006: MON,TUE,WED,THU,FRI,SAT,SUN | I5006: 1A,2A,3A,CC,FC,SL,2S,3E,GN | J5006: Rajgir (arr=First,dep=07:00) | Sardar Patel H (arr=07:03,dep=07:04) | Karahdih H (arr=07:07,dep=07:08) | Silao (arr=07:11,dep=07:12) | Mahuri H (arr=07:15,dep=07:16) | Nalanda (arr=07:19,dep=07:20) | Deepnagar H (arr=07:24,dep=07:25) | Pawapuri Road Halt (arr=07:33,dep=07:34) | Tungi H (arr=07:37,dep=07:38) | Bihar Sharif (arr=07:59,dep=08:01) | Sohsarai (arr=08:07,dep=08:08) | Dekpura Jn (arr=08:12,dep=08:13) | Noorsarai H (arr=08:24,dep=08:25) | Badhuna H (arr=08:31,dep=08:32) | Chandi H (arr=08:39,dep=08:40) | Rukhai H (arr=08:44,dep=08:45) | Lachhubigha H (arr=08:53,dep=08:54) | Sultanpur Gram (arr=08:59,dep=09:00) | Daniyawan Jn (arr=09:23,dep=09:25) | Daniyawan Bazar H (arr=09:29,dep=09:31) | Naika Road H (arr=09:36,dep=09:37) | Machriawan H (arr=09:41,dep=09:42) | Gokulnagar H (arr=09:46,dep=09:47) | Fatuha (arr=10:25,dep=Last)
A5007: 53230 | B5007: FUT-RGD PASSENGER | C5007: Fatuha | D5007: 17:45 | E5007: 21:25 | F5007: 68 | G5007: Rajgir | H5007: MON,TUE,WED,THU,FRI,SAT,SUN | J5007: Fatuha (arr=First,dep=17:45) | Gokulnagar H (arr=17:51,dep=17:52) | Machriawan H (arr=17:56,dep=17:57) | Naika Road H (arr=18:01,dep=18:02) | Daniyawan Bazar H (arr=18:05,dep=18:07) | Daniyawan Jn (arr=18:19,dep=18:21) | Sultanpur Gram (arr=18:32,dep=18:33) | Lachhubigha H (arr=18:39,dep=18:40) | Rukhai H (arr=18:46,dep=18:47) | Chandi H (arr=18:51,dep=18:52) | Badhuna H (arr=18:59,dep=19:00) | Noorsarai H (arr=19:07,dep=19:08) | Dekpura Jn (arr=19:20,dep=19:21) | Sohsarai (arr=19:25,dep=19:26) | Bihar Sharif (arr=19:35,dep=19:37) | Tungi H (arr=19:41,dep=19:42) | Pawapuri Road Halt (arr=19:48,dep=19:49) | Deepnagar H (arr=19:53,dep=19:54) | Nalanda (arr=20:00,dep=20:02) | Mahuri H (arr=20:06,dep=20:07) | Silao (arr=20:19,dep=20:20) | Karahdih H (arr=20:24,dep=20:25) | Sardar Patel H (arr=20:29,dep=20:30) | Rajgir (arr=21:25,dep=Last)
A5008: 53231 | B5008: TIA-DNR PASSENGER Train | C5008: Tilaiya | D5008: 17:30 | E5008: 1:35 | F5008: 152 | G5008: Danapur | H5008: MON,TUE,WED,THU,FRI,SAT,SUN | I5008: 1A,2A,3A,CC,FC,SL,2S,3E,GN | J5008: Tilaiya (arr=First,dep=17:30) | Hisua (arr=17:39,dep=17:40) | Mohamadpur (arr=17:44,dep=17:45) | Jagdishpur (arr=17:51,dep=17:53) | Sarsoo (arr=18:07,dep=18:08) | Jethian (arr=18:16,dep=18:18) | Natesar (arr=18:29,dep=18:31) | Nekpur (arr=18:44,dep=18:45) | Rajgir (arr=19:00,dep=19:05) | Karahdih H (arr=19:12,dep=19:13) | Silao (arr=19:17,dep=19:19) | Nalanda (arr=19:25,dep=19:27) | Deepnagar H (arr=19:33,dep=19:34) | Pawapuri Road Halt (arr=19:38,dep=19:40) | Tungi H (arr=19:45,dep=19:46) | Bihar Sharif (arr=19:53,dep=19:58) | Sohsarai (arr=20:03,dep=20:04) | Dekpura Jn (arr=20:09,dep=20:10) | Ambapendarpur H (arr=20:13,dep=20:14) | Rahui Road (arr=20:17,dep=20:18) | Imlibhaga Halt (arr=20:23,dep=20:24) | Wena (arr=20:28,dep=20:30) | Murhari H (arr=20:35,dep=20:36) | Harnaut (arr=20:40,dep=20:42) | Kharuara Halt (arr=20:47,dep=20:48) | Karnauti H (arr=20:53,dep=20:54) | Bakhtiyarpur Jn (arr=21:36,dep=21:38) | Salimpur Bihar (arr=21:48,dep=21:49) | Karauta (arr=21:53,dep=21:55) | Khusropur (arr=22:03,dep=22:05) | Hardas Bigha (arr=22:09,dep=22:10) | Fatuha (arr=22:25,dep=22:27) | Banka Ghat (arr=22:34,dep=22:36) | Deedar Ganj (arr=22:40,dep=22:41) | Patna Saheb (arr=22:50,dep=22:52) | Gulzarbagh (arr=22:58,dep=23:00) | Rajendranagar T (arr=23:08,dep=23:10) | Patna Jn (arr=00:05,dep=00:10) | Sachiwalay Halt (arr=00:18,dep=00:20) | Phulwari Sharif (arr=00:26,dep=00:28) | Danapur (arr=01:35,dep=Last)
A5009: 53232 | B5009: DNR-TIA PASSENGER | C5009: Danapur | D5009: 8:50 | E5009: 15:45 | F5009: 152 | G5009: Tilaiya | H5009: MON,TUE,WED,THU,FRI,SAT,SUN | I5009: GN | J5009: Danapur (arr=First,dep=08:50) | Phulwari Sharif (arr=08:58,dep=09:00) | Sachiwalay Halt (arr=09:06,dep=09:08) | Patna Jn (arr=09:25,dep=09:30) | Rajendranagar T (arr=09:36,dep=09:38) | Gulzarbagh (arr=09:44,dep=09:46) | Patna Saheb (arr=09:52,dep=09:54) | Banka Ghat (arr=10:04,dep=10:06) | Fatuha (arr=10:20,dep=10:22) | Hardas Bigha (arr=10:31,dep=10:32) | Khusropur (arr=10:36,dep=10:38) | Karauta (arr=10:46,dep=10:48) | Salimpur Bihar (arr=10:52,dep=10:53) | Bakhtiyarpur Jn (arr=11:10,dep=11:12) | Karnauti H (arr=11:20,dep=11:21) | Kharuara Halt (arr=11:26,dep=11:27) | Harnaut (arr=11:31,dep=11:33) | Murhari H (arr=11:39,dep=11:40) | Wena (arr=11:43,dep=11:45) | Imlibhaga Halt (arr=11:52,dep=11:53) | Rahui Road (arr=11:57,dep=11:58) | Ambapendarpur H (arr=12:00,dep=12:01) | Dekpura Jn (arr=12:03,dep=12:04) | Sohsarai (arr=12:08,dep=12:09) | Bihar Sharif (arr=12:12,dep=12:14) | Tungi H (arr=12:21,dep=12:22) | Pawapuri Road Halt (arr=12:26,dep=12:28) | Deepnagar H (arr=12:35,dep=12:36) | Nalanda (arr=12:39,dep=12:41) | Silao (arr=12:50,dep=12:52) | Karahdih H (arr=12:57,dep=12:58) | Rajgir (arr=13:15,dep=13:20) | Nekpur (arr=13:28,dep=13:29) | Natesar (arr=13:38,dep=13:40) | Jethian (arr=13:47,dep=13:49) | Sarsoo (arr=13:58,dep=13:59) | Jagdishpur (arr=14:10,dep=14:12) | Mohamadpur (arr=14:20,dep=14:21) | Hisua (arr=14:25,dep=14:26) | Tilaiya (arr=15:45,dep=Last)
A5010: 53233 | B5010: NES-FUT PASSENGER Train | C5010: Natesar | D5010: 15:05 | E5010: 17:15 | F5010: 62 | G5010: Fatuha | H5010: MON,TUE,WED,THU,FRI,SAT,SUN | I5010: 1A,2A,3A,CC,FC,SL,2S,3E,GN | J5010: Natesar (arr=First,dep=15:05) | Katari (arr=15:10,dep=15:12) | Harsingra Halt (arr=15:21,dep=15:22) | Khudaganj Bazar (arr=15:28,dep=15:30) | Islampur (arr=15:55,dep=16:00) | Aungaridham H (arr=16:06,dep=16:07) | Ekangar Sarai F (arr=16:11,dep=16:13) | Hilsa Block (arr=16:23,dep=16:25) | Daniyawan Bazar H (arr=16:46,dep=16:48) | Fatuha (arr=17:15,dep=Last)
A5011: 53234 | B5011: FUT-NES PASSENGER | C5011: Fatuha | D5011: 10:30 | E5011: 13:00 | F5011: 62 | G5011: Natesar | H5011: MON,TUE,WED,THU,FRI,SAT,SUN | J5011: Fatuha (arr=First,dep=10:30) | Daniyawan Bazar H (arr=10:41,dep=10:43) | Hilsa Block (arr=11:12,dep=11:14) | Ekangar Sarai F (arr=11:25,dep=11:27) | Aungaridham H (arr=11:33,dep=11:34) | Islampur (arr=11:40,dep=11:42) | Khudaganj Bazar (arr=11:51,dep=11:52) | Harsingra Halt (arr=11:59,dep=12:00) | Katari (arr=12:08,dep=12:09) | Natesar (arr=13:00,dep=Last)
A5012: 53235 | B5012: HIL-FUT PASSENGER Train | C5012: Hilsa Block | D5012: 15:00 | E5012: 16:10 | F5012: 20 | G5012: Fatuha | H5012: MON,TUE,WED,THU,FRI,SAT,SUN | I5012: 1A,2A,3A,CC,FC,SL,2S,3E,GN | J5012: Hilsa Block (arr=First,dep=15:00) | Kamta Halt (arr=15:04,dep=15:05) | Lohanda H (arr=15:10,dep=15:11) | Diyawan H (arr=15:16,dep=15:17) | Singriyawan H (arr=15:22,dep=15:23) | Daniyawan Jn (arr=15:27,dep=15:29) | Daniyawan Bazar H (arr=15:32,dep=15:34) | Naika Road H (arr=15:38,dep=15:39) | Machriawan H (arr=15:42,dep=15:43) | Gokulnagar H (arr=15:46,dep=15:47) | Fatuha (arr=16:10,dep=Last)
A5013: 53236 | B5013: FUT-HIL PASSENGER Train | C5013: Fatuha | D5013: 12:30 | E5013: 13:45 | F5013: 20 | G5013: Hilsa Block | H5013: MON,TUE,WED,THU,FRI,SAT,SUN | I5013: 1A,2A,3A,CC,FC,SL,2S,3E,GN | J5013: Fatuha (arr=First,dep=12:30) | Gokulnagar H (arr=12:35,dep=12:36) | Machriawan H (arr=12:39,dep=12:40) | Naika Road H (arr=12:43,dep=12:44) | Daniyawan Bazar H (arr=12:46,dep=12:48) | Daniyawan Jn (arr=12:52,dep=12:53) | Singriyawan H (arr=13:00,dep=13:01) | Diyawan H (arr=13:06,dep=13:07) | Lohanda H (arr=13:12,dep=13:13) | Kamta Halt (arr=13:16,dep=13:17) | Hilsa Block (arr=13:45,dep=Last)
A5014: 53237 | B5014: PNBE-GAYA PASSENGER Train | C5014: Patna Jn | D5014: 18:10 | E5014: 20:30 | F5014: 92 | G5014: Gaya Jn | H5014: MON,TUE,WED,THU,FRI,SAT,SUN | I5014: 1A,2A,3A,CC,FC,SL,2S,3E,GN | J5014: Patna Jn (arr=First,dep=18:10) | Punpun (arr=18:26,dep=18:31) | Taregna (arr=18:41,dep=18:43) | Jehanabad (arr=19:01,dep=19:03) | Makhdumpur Gaya (arr=19:23,dep=19:25) | Gaya Jn (arr=20:30,dep=Last)
A5015: 53238 | B5015: GAYA-PNBE PASSENGER Train | C5015: Gaya Jn | D5015: 5:20 | E5015: 8:15 | F5015: 92 | G5015: Patna Jn | H5015: MON,TUE,WED,THU,FRI,SAT,SUN | I5015: 1A,2A,3A,CC,FC,SL,2S,3E,GN | J5015: Gaya Jn (arr=First,dep=05:20) | Chakand (arr=05:32,dep=05:34) | Bela (arr=05:43,dep=05:45) | Makhdumpur Gaya (arr=05:54,dep=05:56) | Tehta (arr=06:02,dep=06:04) | Jehanabad (arr=06:14,dep=06:16) | Karona H (arr=06:22,dep=06:23) | Seonan H (arr=06:26,dep=06:27) | Nadaul (arr=06:30,dep=06:31) | Teneri H (arr=06:35,dep=06:36) | Chhotaki Masaudhi H (arr=06:39,dep=06:40) | Taregna (arr=06:43,dep=06:45) | Masaudhi Court H (arr=06:50,dep=06:51) | Nadwan (arr=06:56,dep=06:57) | Nema H (arr=07:01,dep=07:02) | Potahi (arr=07:07,dep=07:08) | Jatdumri H (arr=07:13,dep=07:14) | Punpun (arr=07:18,dep=07:19) | Punpun Ghat H (arr=07:23,dep=07:24) | Ramgovindsingh Mahuli H (arr=07:27,dep=07:28) | Parsa Bazar (arr=07:33,dep=07:34) | Patna Jn (arr=08:15,dep=Last)
A5016: 53239 | B5016: PNBE-GAYA PASSENGER Train | C5016: Patna Jn | D5016: 9:30 | E5016: 13:15 | F5016: 92 | G5016: Gaya Jn | H5016: MON,TUE,WED,THU,FRI,SAT,SUN | I5016: 1A,2A,3A,CC,FC,SL,2S,3E,GN | J5016: Patna Jn (arr=First,dep=09:30) | Parsa Bazar (arr=09:42,dep=09:43) | Ramgovindsingh Mahuli H (arr=09:48,dep=09:49) | Punpun Ghat H (arr=09:52,dep=09:53) | Punpun (arr=09:56,dep=09:57) | Jatdumri H (arr=10:01,dep=10:02) | Potahi (arr=10:06,dep=10:07) | Nema H (arr=10:12,dep=10:13) | Nadwan (arr=10:16,dep=10:17) | Masaudhi Court H (arr=10:22,dep=10:23) | Taregna (arr=10:26,dep=10:28) | Chhotaki Masaudhi H (arr=10:32,dep=10:33) | Teneri H (arr=10:37,dep=10:38) | Nadaul (arr=10:41,dep=10:42) | Seonan H (arr=10:46,dep=10:47) | Karona H (arr=10:50,dep=10:51) | Jehanabad (arr=11:03,dep=11:05) | Jahanabad Court F (arr=11:10,dep=11:11) | Mai Halt (arr=11:15,dep=11:16) | Niyazipur H (arr=11:19,dep=11:20) | Mirabigha Halt (arr=11:23,dep=11:24) | Tehta (arr=11:27,dep=11:28) | Makhdumpur Gaya (arr=11:35,dep=11:36) | Wanwar Koteshwarnath Dham (arr=11:40,dep=11:41) | Ner H (arr=11:46,dep=11:47) | Barabar H (arr=11:49,dep=11:50) | Bela (arr=11:55,dep=11:56) | Neyamatpur H (arr=12:02,dep=12:03) | Ore Halt (arr=12:06,dep=12:07) | Chakand (arr=12:15,dep=12:16) | Gaya Jn (arr=13:15,dep=Last)
A5017: 53240 | B5017: GAYA-PNBE-PASSENGER Train | C5017: Gaya Jn | D5017: 14:10 | E5017: 17:10 | F5017: 92 | G5017: Patna Jn | H5017: MON,TUE,WED,THU,FRI,SAT,SUN | I5017: 1A,2A,3A,CC,FC,SL,2S,3E,GN | J5017: Gaya Jn (arr=First,dep=14:10) | Chakand (arr=14:23,dep=14:24) | Ore Halt (arr=14:28,dep=14:29) | Neyamatpur H (arr=14:32,dep=14:33) | Bela (arr=14:38,dep=14:39) | Barabar H (arr=14:43,dep=14:44) | Ner H (arr=14:47,dep=14:48) | Wanwar Koteshwarnath Dham (arr=14:53,dep=14:54) | Makhdumpur Gaya (arr=14:57,dep=14:58) | Tehta (arr=15:04,dep=15:05) | Mirabigha Halt (arr=15:08,dep=15:09) | Niyazipur H (arr=15:12,dep=15:13) | Mai Halt (arr=15:16,dep=15:17) | Jahanabad Court F (arr=15:21,dep=15:22) | Jehanabad (arr=15:26,dep=15:28) | Karona H (arr=15:33,dep=15:34) | Seonan H (arr=15:38,dep=15:39) | Nadaul (arr=15:42,dep=15:43) | Teneri H (arr=15:46,dep=15:47) | Chhotaki Masaudhi H (arr=15:51,dep=15:52) | Taregna (arr=15:57,dep=15:59) | Masaudhi Court H (arr=16:03,dep=16:04) | Nadwan (arr=16:09,dep=16:10) | Nema H (arr=16:13,dep=16:14) | Potahi (arr=16:19,dep=16:20) | Jatdumri H (arr=16:25,dep=16:26) | Punpun (arr=16:30,dep=16:31) | Punpun Ghat H (arr=16:34,dep=16:35) | Ramgovindsingh Mahuli H (arr=16:39,dep=16:40) | Parsa Bazar (arr=16:45,dep=16:46) | Patna Jn (arr=17:10,dep=Last)
A5018: 53241 | B5018: GAH-NKE PASSENGER Train | C5018: Gawnaha | D5018: 14:15 | E5018: 15:10 | F5018: 23 | G5018: Narkatiaganj Jn | H5018: MON,TUE,WED,THU,FRI,SAT,SUN | I5018: 1A,2A,3A,CC,FC,SL,2S,3E,GN | J5018: Gawnaha (arr=First,dep=14:15) | Bhitiharwa Ashram F (arr=14:29,dep=14:30) | Amolwa (arr=14:38,dep=14:40) | Narkatiaganj Jn (arr=15:10,dep=Last)
...

Sheet 🔢 Calculations
A1: CALCULATION REFERENCE SHEET — Indian Railways Train Dataset
A3: SECTION A | KPI Base Calculations
A4: Metric | B4: Formula Used | C4: Value | D4: Notes
A5: Total Train Records | B5: =COUNTA('📋 Raw Data'!A:A)-1 -> 8366 | C5: =COUNTA('📋 Raw Data'!A:A)-1 -> 8366 | D5: Count of all data rows
A6: Total Distance (km) | B6: =SUM('📋 Raw Data'!F2:F8367) -> 5018304 | C6: =SUM('📋 Raw Data'!F2:F8367) -> 5018304 | D6: Sum of distance column
A7: Average Distance (km) | B7: =AVERAGE('📋 Raw Data'!F2:F8367) -> 599.84509 | C7: =AVERAGE('📋 Raw Data'!F2:F8367) -> 599.84509 | D7: Mean distance per train
A8: Max Distance (km) | B8: =MAX('📋 Raw Data'!F2:F8367) -> 4189 | C8: =MAX('📋 Raw Data'!F2:F8367) -> 4189 | D8: Longest route
A9: Min Distance (km) | B9: =MIN('📋 Raw Data'!F2:F8367) -> 2 | C9: =MIN('📋 Raw Data'!F2:F8367) -> 2 | D9: Shortest route
A10: Median Distance (km) | B10: =MEDIAN('📋 Raw Data'!F2:F8367) -> 290 | C10: =MEDIAN('📋 Raw Data'!F2:F8367) -> 290 | D10: 50th percentile distance
A11: Std Dev Distance | B11: =STDEV('📋 Raw Data'!F2:F8367) -> 712.96643 | C11: =STDEV('📋 Raw Data'!F2:F8367) -> 712.96643 | D11: Variability in distance
A12: Unique Source Stations | B12: =SUMPRODUCT(1/COUNTIF('📋 Raw Data'!C2:C8367,'📋 Raw Data'!C2:C8367)) -> 1034 | C12: =SUMPRODUCT(1/COUNTIF('📋 Raw Data'!C2:C8367,'📋 Raw Data'!C2:C8367)) -> 1034 | D12: Distinct source stations
A15: SECTION B | Distance Category Pivot Table
A16: Distance Category | B16: Train Count | C16: % Share | D16: Avg Distance | E16: Avg Stops
A17: Short (<200 km) | B17: 3400 | C17: =B17/SUM(B17:B20) -> 0.40640689 | D17: 105.8 | E17: 14.1
A18: Medium (200-500 km) | B18: 1892 | C18: =B18/SUM(B17:B20) -> 0.22615348 | D18: 333.4 | E18: 24.1
A19: Long (500-1000 km) | B19: 1380 | C19: =B19/SUM(B17:B20) -> 0.16495338 | D19: 721.3 | E19: 23.8
A20: Very Long (>1000 km) | B20: 1694 | C20: =B20/SUM(B17:B20) -> 0.20248625 | D20: 1584.1 | E20: 30.2
A21: TOTAL | B21: =SUM(B17:B20) -> 8366 | C21: =SUM(C17:C20) -> 1
A24: SECTION C | Departure Time Slot Pivot Table
A25: Departure Slot | B25: Train Count | C25: % Share | D25: Avg Distance (km) | E25: Frequency Rank
A26: Morning (6-12) | B26: 2346 | C26: =B26/SUM(B26:B29) -> 0.28042075 | D26: 518 | E26: =RANK(B26,B26:B29,0) -> 1
A27: Afternoon (12-17) | B27: 2204 | C27: =B27/SUM(B26:B29) -> 0.26344729 | D27: 618.1 | E27: =RANK(B27,B26:B29,0) -> 2
A28: Evening (17-21) | B28: 1814 | C28: =B28/SUM(B26:B29) -> 0.21683003 | D28: 595 | E28: =RANK(B28,B26:B29,0) -> 4
A29: Night (21-6) | B29: 2002 | C29: =B29/SUM(B26:B29) -> 0.23930194 | D29: 680.1 | E29: =RANK(B29,B26:B29,0) -> 3
A32: SECTION D | Class Availability Analysis
A33: Class Code | B33: Class Name | C33: Trains Available | D33: % Coverage | E33: Ranking
A34: 1A | B34: AC First Class | C34: 6869 | D34: =C34/8366 -> 0.82106144 | E34: =RANK(C34,C34:C42,0) -> 5
A35: 2A | B35: AC 2-Tier | C35: 7129 | D35: =C35/8366 -> 0.85213961 | E35: =RANK(C35,C34:C42,0) -> 4
A36: 3A | B36: AC 3-Tier | C36: 7215 | D36: =C36/8366 -> 0.86241932 | E36: =RANK(C36,C34:C42,0) -> 3
A37: CC | B37: AC Chair Car | C37: 6728 | D37: =C37/8366 -> 0.80420751 | E37: =RANK(C37,C34:C42,0) -> 8
A38: FC | B38: First Class | C38: 6560 | D38: =C38/8366 -> 0.78412623 | E38: =RANK(C38,C34:C42,0) -> 9
A39: SL | B39: Sleeper Class | C39: 7304 | D39: =C39/8366 -> 0.87305761 | E39: =RANK(C39,C34:C42,0) -> 2
A40: 2S | B40: Second Sitting | C40: 6735 | D40: =C40/8366 -> 0.80504423 | E40: =RANK(C40,C34:C42,0) -> 7
A41: 3E | B41: AC 3-Tier Economy | C41: 6776 | D41: =C41/8366 -> 0.80994502 | E41: =RANK(C41,C34:C42,0) -> 6
A42: GN | B42: General/Unreserved | C42: 8147 | D42: =C42/8366 -> 0.97382262 | E42: =RANK(C42,C34:C42,0) -> 1

Sheet 📊 Pivot Tables
A1: PIVOT TABLE ANALYSIS | Indian Railways Train Dataset
A3: PIVOT 1 | Distance Category × Metrics Summary
A4: Distance Category | B4: Train Count | C4: % of Total | D4: Avg Distance | E4: Min Dist | F4: Max Dist | G4: Avg Stops | H4: Cumulative %
A5: Short (<200 km) | B5: 3400 | C5: =B5/SUM(B5:B8) -> 0.40640689 | D5: 105.8 | E5: 2 | F5: 199 | G5: 14.1 | H5: =SUM(B5:B5)/SUM(B5:B8) -> 0.40640689
A6: Medium (200-500 km) | B6: 1892 | C6: =B6/SUM(B5:B8) -> 0.22615348 | D6: 333.4 | E6: 200 | F6: 499 | G6: 24.1 | H6: =SUM(B5:B6)/SUM(B5:B8) -> 0.63256036
A7: Long (500-1000 km) | B7: 1380 | C7: =B7/SUM(B5:B8) -> 0.16495338 | D7: 721.3 | E7: 500 | F7: 999 | G7: 23.8 | H7: =SUM(B5:B7)/SUM(B5:B8) -> 0.79751375
A8: Very Long (>1000 km) | B8: 1694 | C8: =B8/SUM(B5:B8) -> 0.20248625 | D8: 1584.1 | E8: 1000 | F8: 4189 | G8: 30.2 | H8: =SUM(B5:B8)/SUM(B5:B8) -> 1
A9: GRAND TOTAL | B9: =SUM(B5:B8) -> 8366 | C9: =SUM(C5:C8) -> 1 | D9: =AVERAGE(D5:D8) -> 686.15 | E9: =MIN(E5:E8) -> 2 | F9: =MAX(F5:F8) -> 4189 | G9: =AVERAGE(G5:G8) -> 23.05
A12: PIVOT 2 | Departure Time Slot × Distance Analysis
A13: Time Slot | B13: Train Count | C13: % Share | D13: Avg Distance | E13: Max Distance | F13: Min Distance | G13: Avg Stops | H13: Performance Index
A14: Morning (6-12) | B14: 2346 | C14: =B14/SUM(B14:B17) -> 0.28042075 | D14: 518 | E14: 3812 | F14: 2 | G14: 21.1 | H14: =D14/AVERAGE(D14:D17)*100 -> 85.932316
A15: Afternoon (12-17) | B15: 2204 | C15: =B15/SUM(B14:B17) -> 0.26344729 | D15: 618.1 | E15: 4189 | F15: 2 | G15: 24.2 | H15: =D15/AVERAGE(D14:D17)*100 -> 102.53816
A16: Evening (17-21) | B16: 1814 | C16: =B16/SUM(B14:B17) -> 0.21683003 | D16: 595 | E16: 3782 | F16: 2 | G16: 22.8 | H16: =D16/AVERAGE(D14:D17)*100 -> 98.706038
A17: Night (21-6) | B17: 2002 | C17: =B17/SUM(B14:B17) -> 0.23930194 | D17: 680.1 | E17: 4072 | F17: 2 | G17: 23.9 | H17: =D17/AVERAGE(D14:D17)*100 -> 112.82349
A18: GRAND TOTAL | B18: =SUM(B14:B17) -> 8366 | C18: =SUM(C14:C17) -> 1 | D18: =AVERAGE(D14:D17) -> 602.8 | E18: =MAX(E14:E17) -> 4189 | F18: =MIN(F14:F17) -> 2 | G18: =AVERAGE(G14:G17) -> 23
A21: PIVOT 3 | Class Availability × Coverage Analysis
A22: Class Code | B22: Class Description | C22: Trains w/ Class | D22: % Coverage | E22: Trains Without | F22: Coverage Rank
A23: 1A | B23: AC First Class | C23: 6869 | D23: =C23/8366 -> 0.82106144 | E23: =8366-C23 -> 1497 | F23: =RANK(C23,C23:C31,0) -> 5
A24: 2A | B24: AC 2-Tier Sleeper | C24: 7129 | D24: =C24/8366 -> 0.85213961 | E24: =8366-C24 -> 1237 | F24: =RANK(C24,C23:C31,0) -> 4
A25: 3A | B25: AC 3-Tier Sleeper | C25: 7215 | D25: =C25/8366 -> 0.86241932 | E25: =8366-C25 -> 1151 | F25: =RANK(C25,C23:C31,0) -> 3
A26: CC | B26: AC Chair Car | C26: 6728 | D26: =C26/8366 -> 0.80420751 | E26: =8366-C26 -> 1638 | F26: =RANK(C26,C23:C31,0) -> 8
A27: FC | B27: First Class (Non-AC) | C27: 6560 | D27: =C27/8366 -> 0.78412623 | E27: =8366-C27 -> 1806 | F27: =RANK(C27,C23:C31,0) -> 9
A28: SL | B28: Sleeper Class | C28: 7304 | D28: =C28/8366 -> 0.87305761 | E28: =8366-C28 -> 1062 | F28: =RANK(C28,C23:C31,0) -> 2
A29: 2S | B29: Second Sitting | C29: 6735 | D29: =C29/8366 -> 0.80504423 | E29: =8366-C29 -> 1631 | F29: =RANK(C29,C23:C31,0) -> 7
A30: 3E | B30: AC 3-Tier Economy | C30: 6776 | D30: =C30/8366 -> 0.80994502 | E30: =8366-C30 -> 1590 | F30: =RANK(C30,C23:C31,0) -> 6
A31: GN | B31: General/Unreserved | C31: 8147 | D31: =C31/8366 -> 0.97382262 | E31: =8366-C31 -> 219 | F31: =RANK(C31,C23:C31,0) -> 1
A34: PIVOT 4 | Top 10 Source Stations by Train Volume
A35: Rank | B35: Source Station | C35: Train Count | D35: % Share | E35: Cumulative %
A36: 1 | B36: Howrah Jn | C36: 123 | D36: =C36/8366 -> 0.014702367 | E36: =SUM(C36:C36)/8366 -> 0.014702367
A37: 2 | B37: Delhi | C37: 98 | D37: =C37/8366 -> 0.011714081 | E37: =SUM(C36:C37)/8366 -> 0.026416448
A38: 3 | B38: New Delhi | C38: 96 | D38: =C38/8366 -> 0.011475018 | E38: =SUM(C36:C38)/8366 -> 0.037891465
A39: 4 | B39: Patna Jn | C39: 86 | D39: =C39/8366 -> 0.010279704 | E39: =SUM(C36:C39)/8366 -> 0.048171169
A40: 5 | B40: Ksr Bengaluru | C40: 79 | D40: =C40/8366 -> 0.0094429835 | E40: =SUM(C36:C40)/8366 -> 0.057614153
A41: 6 | B41: Mgr Chennai Ctr | C41: 77 | D41: =C41/8366 -> 0.0092039206 | E41: =SUM(C36:C41)/8366 -> 0.066818073
A42: 7 | B42: Puri | C42: 68 | D42: =C42/8366 -> 0.0081281377 | E42: =SUM(C36:C42)/8366 -> 0.074946211
A43: 8 | B43: Visakhapatnam | C43: 66 | D43: =C43/8366 -> 0.0078890748 | E43: =SUM(C36:C43)/8366 -> 0.082835286
A44: 9 | B44: Anand Vihar Terminal | C44: 61 | D44: =C44/8366 -> 0.0072914176 | E44: =SUM(C36:C44)/8366 -> 0.090126703
A45: 10 | B45: Tirupati | C45: 59 | D45: =C45/8366 -> 0.0070523548 | E45: =SUM(C36:C45)/8366 -> 0.097179058
A48: PIVOT 5 | Top 10 Destination Stations by Train Volume
A49: Rank | B49: Destination Station | C49: Train Count | D49: % Share | E49: Cumulative %
...

Sheet 📐 Formula Reference
A1: FORMULA REFERENCE GUIDE | All Formulas Used in This Dashboard
A3: EXCEL FORMULAS — ANALYTICAL REFERENCE
A4: # | B4: Formula Name | C4: Formula Syntax | D4: Category | E4: Purpose / Description | F4: Used In Sheet | G4: Output Type
A5: 1 | B5: COUNTA | C5: =COUNTA('📋 Raw Data'!A:A)-1 -> 8366 | D5: Count | E5: Counts total train records (non-blank cells) | F5: 🏆 DASHBOARD | G5: Integer
A6: 2 | B6: SUM | C6: =SUM('📋 Raw Data'!F2:F8367) -> 5018304 | D6: Aggregation | E6: Adds all distances to get total km operated | F6: 🔢 Calculations | G6: Number
A7: 3 | B7: AVERAGE | C7: =AVERAGE('📋 Raw Data'!F2:F8367) -> 599.84509 | D7: Statistics | E7: Calculates mean route distance across all trains | F7: 🏆 DASHBOARD | G7: Decimal
A8: 4 | B8: MAX | C8: =MAX('📋 Raw Data'!F2:F8367) -> 4189 | D8: Statistics | E8: Finds the longest single train route | F8: 🏆 DASHBOARD | G8: Number
A9: 5 | B9: MIN | C9: =MIN('📋 Raw Data'!F2:F8367) -> 2 | D9: Statistics | E9: Finds the shortest single train route | F9: 🔢 Calculations | G9: Number
A10: 6 | B10: MEDIAN | C10: =MEDIAN('📋 Raw Data'!F2:F8367) -> 290 | D10: Statistics | E10: 50th percentile — half routes above, half below | F10: 🔢 Calculations | G10: Decimal
A11: 7 | B11: STDEV | C11: =STDEV('📋 Raw Data'!F2:F8367) -> 712.96643 | D11: Statistics | E11: Measures variability/spread in train distances | F11: 🔢 Calculations | G11: Decimal
A12: 8 | B12: RANK | C12: RANK(C,range,0) — e.g. =RANK(C34,C4:C2,0) | D12: Ranking | E12: Ranks class by availability count (descending) | F12: 📊 Pivot Tables | G12: Integer
A13: 9 | B13: % Share | C13: B/SUM(B:B) — e.g. =B5/SUM(B$5:B$8) | D13: Ratio | E13: Calculates each category's share of total trains | F13: 📊 Pivot Tables | G13: Percentage
A14: 10 | B14: Cum. % | C14: SUM(B$s:Bi)/SUM(B$s:B$e) — running cumulative % | D14: Cumulative | E14: Running total percentage for Pareto analysis | F14: 📊 Pivot Tables | G14: Percentage
A15: 11 | B15: Coverage % | C15: C_class/8366 — e.g. =C34/8366 | D15: Ratio | E15: What % of all trains offer a specific class | F15: 📊 Pivot Tables | G15: Percentage
A16: 12 | B16: Without | C16: 8366-C_class — e.g. =8366-C34 | D16: Arithmetic | E16: Trains NOT offering a specific class | F16: 📊 Pivot Tables | G16: Integer
A17: 13 | B17: Perf. Index | C17: D_slot/AVERAGE(D$s:D$e)*100 — index formula | D17: Index | E17: Benchmarks slot avg vs overall avg (base=100) | F17: 📊 Pivot Tables | G17: Decimal
A18: 14 | B18: SUMPRODUCT | C18: SUMPRODUCT(1/COUNTIF(rng,rng)) — unique count | D18: Advanced | E18: Counts unique values without helper column | F18: 🔢 Calculations | G18: Integer
A19: 15 | B19: IF+COUNTIF | C19: IF(COUNTIF(rng,val)>0,'Yes','No') — presence check | D19: Lookup | E19: Checks class availability for a train | F19: 📊 Pivot Tables | G19: Text
A20: 16 | B20: Grand Total | C20: SUM(B_start:B_end) — grand total aggregation | D20: Aggregation | E20: Totals all sub-category values in a pivot table | F20: 📊 Pivot Tables | G20: Integer
A21: 17 | B21: Avg Stops | C21: AVERAGE(stops_column_range) — mean stops | D21: Statistics | E21: Mean intermediate stops per distance category | F21: 📊 Pivot Tables | G21: Decimal
A22: 18 | B22: IFERROR | C22: IFERROR(formula,0) — error guard wrapper | D22: Error Guard | E22: Sum of matching-class trains / 8366 | F22: All Sheets | G22: Any
A25: DASHBOARD COLOR CODING LEGEND
B26: Color / Style | C26: Color Name | E26: Meaning / Convention
B27: ████ Sample | C27: Blue Text / Blue Fill | E27: Hardcoded input values — numbers users can change
B28: ████ Sample | C28: Black Text | E28: Formula-calculated values — auto-update with data
B29: ████ Sample | C29: Purple Italic | E29: Formula syntax display — shown in formula bar
B30: ████ Sample | C30: Green Text | E30: Cross-sheet references — pulling from another tab
B31: ████ Sample | C31: Light Blue Row Fill | E31: Alternating row shading for readability
B32: ████ Sample | C32: Dark Navy Header | E32: Section headers and primary table headers
B33: ████ Sample | C33: Medium Blue Header | E33: Sub-section headers and column headers
B34: ████ Sample | C34: Orange Accent | E34: Departure time analysis sections
B35: ████ Sample | C35: Teal Accent | E35: Destination and supplementary analysis
B36: ████ Sample | C36: Gold Accent | E36: KPI highlights and top-rank indicators

Sheet 🏆 DASHBOARD
A2: 🚂 INDIAN RAILWAYS TRAIN NETWORK | ANALYTICS DASHBOARD
B3: Dataset: 8,366 Trains | Source: Train_Data.csv | Prepared by: Analytics Team | Date: May 2026
B4: TOTAL TRAINS | D4: AVG DISTANCE | F4: MAX DISTANCE | H4: DAILY TRAINS | J4: AVG STOPS | L4: SHORT ROUTES (<200km) | N4: UNIQUE CLASSES
B5: =COUNTA('📋 Raw Data'!A:A)-1 -> 8366 | D5: =AVERAGE('📋 Raw Data'!F2:F8367) -> 599.84509 | F5: =MAX('📋 Raw Data'!F2:F8367) -> 4189 | H5: 7861 | J5: =AVERAGE('🔢 Calculations'!C5:C5) -> 8366 | L5: 3400 | N5: 9
B7: Total records in dataset | D7: Mean route distance | F7: Longest single route | H7: Run all 7 days/week | J7: Mean intermediate stops | L7: 40.6% of all trains | N7: Train class types available
B53: KEY STATISTICS SUMMARY TABLE
B54: Metric | E54: Value | G54: Formula Used | K54: Insight | O54: Ref
B55: Total Train Records | E55: =COUNTA('📋 Raw Data'!A:A)-1 -> 8366 | G55: =COUNTA('📋 Raw Data'!A:A)-1 -> 8366 | K55: Complete dataset coverage | O55: 📋 Raw Data!A
B56: Average Route Distance | E56: =AVERAGE('📋 Raw Data'!F2:F8367) -> 599.84509 | G56: =AVERAGE('📋 Raw Data'!F2:F8367) -> 599.84509 | K56: Moderate-to-long haul focus | O56: 📋 Raw Data!F
B57: Longest Route (km) | E57: =MAX('📋 Raw Data'!F2:F8367) -> 4189 | G57: =MAX('📋 Raw Data'!F2:F8367) -> 4189 | K57: Extreme cross-country service | O57: 📋 Raw Data!F
B58: Shortest Route (km) | E58: =MIN('📋 Raw Data'!F2:F8367) -> 2 | G58: =MIN('📋 Raw Data'!F2:F8367) -> 2 | K58: Very local / metro trains | O58: 📋 Raw Data!F
B59: Median Distance (km) | E59: =MEDIAN('📋 Raw Data'!F2:F8367) -> 290 | G59: =MEDIAN('📋 Raw Data'!F2:F8367) -> 290 | K59: 50% trains below this distance | O59: 📋 Raw Data!F
B60: Daily Frequency Trains | E60: 7861 | G60: Hardcoded value | K60: 93.97% run every day of the week | O60: 🔢 Calculations
B61: Weekly (Selective) Trains | E61: 505 | G61: Hardcoded value | K61: 6.03% run on select days only | O61: 🔢 Calculations
B62: Most Popular Departure Slot | E62: Morning (6-12) | G62: Text value | K62: 2,346 trains — 28.0% of total | O62: 📊 Pivot Tables
B63: Highest Distance Slot | E63: Night (21-6) | G63: Text value | K63: Avg 680.1 km — night long hauls | O63: 📊 Pivot Tables
B64: Top Source Station | E64: Howrah Jn | G64: Text value | K64: 123 trains — busiest origin hub | O64: 📊 Pivot Tables
B65: Top Destination Station | E65: Howrah Jn | G65: Text value | K65: 136 trains — busiest terminus | O65: 📊 Pivot Tables
B66: Most Available Class | E66: GN (General) | G66: Text value | K66: 8,147 trains (97.4% coverage) | O66: 📊 Pivot Tables
B67: Least Available Class | E67: FC (First Class) | G67: Text value | K67: 6,560 trains (78.4% coverage) | O67: 📊 Pivot Tables
B68: Most Common Stop Range | E68: 11-20 Stops | G68: Text value | K68: 2,946 trains — 35.2% of all trains | O68: 📊 Pivot Tables
B69: Avg Intermediate Stops | E69: 21.21 | G69: Hardcoded value | K69: Typical mail/express train profile | O69: 🔢 Calculations
A71: Source: Train_Data.csv | Analysis: All pivot tables & charts reference live formula calculations | Formulas visible in Formula Bar | Built with openpyxl — May 2026
A130: Distance Category | B130: Count
A131: Short (<200km) | B131: 3400
A132: Medium (200-500km) | B132: 1892
A133: Long (500-1000km) | B133: 1380
A134: Very Long (>1000km) | B134: 1694
A137: Departure Slot | B137: Count
A138: Morning (6-12) | B138: 2346
A139: Afternoon (12-17) | B139: 2204
A140: Evening (17-21) | B140: 1814
A141: Night (21-6) | B141: 2002
A144: Class | B144: Trains Available
A145: 1A | B145: 6869
A146: 2A | B146: 7129
A147: 3A | B147: 7215
A148: CC | B148: 6728
A149: FC | B149: 6560
A150: SL | B150: 7304
...
